<?xml version="1.0" encoding="utf-8"?>
<!-- This URDF was automatically created by SolidWorks to URDF Exporter! Originally created by Stephen Brawner (brawner@gmail.com) 
     Commit Version: 1.6.0-4-g7f85cfe  Build Version: 1.6.7995.38578
     For more information, please see http://wiki.ros.org/sw_urdf_exporter -->
<robot
  name="robotic_arm">
  <link
    name="base_link">
    <inertial>
      <origin
        xyz="-4.33680868994202E-18 6.99345186072851E-17 0.005"
        rpy="0 0 0" />
      <mass
        value="0.06" />
      <inertia
        ixx="0.0018005"
        ixy="-4.33680868994204E-22"
        ixz="2.65544173850756E-38"
        iyy="1E-06"
        iyz="1.10183956685168E-19"
        izz="0.0018005" />
    </inertial>
    <visual>
      <origin
        xyz="0 0 0"
        rpy="0 0 0" />
      <geometry>
        <mesh
          filename="package://robotic_arm/meshes/base_link.STL" />
      </geometry>
      <material
        name="">
        <color
          rgba="1 1 1 1" />
      </material>
    </visual>
    <collision>
      <origin
        xyz="0 0 0"
        rpy="0 0 0" />
      <geometry>
        <mesh
          filename="package://robotic_arm/meshes/base_link.STL" />
      </geometry>
    </collision>
  </link>
  <link
    name="shift_link">
    <inertial>
      <origin
        xyz="-0.000493021687784463 0.0117861802404668 -0.0171848786782461"
        rpy="0 0 0" />
      <mass
        value="0.631145310461498" />
      <inertia
        ixx="0.000618095249280658"
        ixy="1.15754977707452E-07"
        ixz="9.67018800173877E-09"
        iyy="0.000974544500585233"
        iyz="-6.72768449957768E-10"
        izz="0.000395201147034481" />
    </inertial>
    <visual>
      <origin
        xyz="0 0 0"
        rpy="0 0 0" />
      <geometry>
        <mesh
          filename="package://robotic_arm/meshes/shift_link.STL" />
      </geometry>
      <material
        name="">
        <color
          rgba="0.752941176470588 0.752941176470588 0.752941176470588 1" />
      </material>
    </visual>
    <collision>
      <origin
        xyz="0 0 0"
        rpy="0 0 0" />
      <geometry>
        <mesh
          filename="package://robotic_arm/meshes/shift_link.STL" />
      </geometry>
    </collision>
  </link>
  <joint
    name="shift_joint"
    type="prismatic">
    <origin
      xyz="0.01 0 0.01"
      rpy="1.5708 0 0" />
    <parent
      link="base_link" />
    <child
      link="shift_link" />
    <axis
      xyz="0 0 1" />
    <limit
      lower="-0.2"
      upper="0.2"
      effort="0"
      velocity="0" />
  </joint>
  <link
    name="yaw_link_1">
    <inertial>
      <origin
        xyz="0.000199351877671859 0.0823520086658196 0.00674975186468349"
        rpy="0 0 0" />
      <mass
        value="1.782506439544" />
      <inertia
        ixx="0.00125834631592565"
        ixy="-2.69255323481454E-06"
        ixz="9.56555153919736E-07"
        iyy="0.00120294090484506"
        iyz="-9.50025090287323E-07"
        izz="0.00216625998994489" />
    </inertial>
    <visual>
      <origin
        xyz="0 0 0"
        rpy="0 0 0" />
      <geometry>
        <mesh
          filename="package://robotic_arm/meshes/yaw_link_1.STL" />
      </geometry>
      <material
        name="">
        <color
          rgba="0.752941176470588 0.752941176470588 0.752941176470588 1" />
      </material>
    </visual>
    <collision>
      <origin
        xyz="0 0 0"
        rpy="0 0 0" />
      <geometry>
        <mesh
          filename="package://robotic_arm/meshes/yaw_link_1.STL" />
      </geometry>
    </collision>
  </link>
  <joint
    name="yaw_joint_1"
    type="revolute">
    <origin
      xyz="0 0.046 -0.017186"
      rpy="3.1416 0 3.1416" />
    <parent
      link="shift_link" />
    <child
      link="yaw_link_1" />
    <axis
      xyz="0 1 0" />
    <limit
      lower="-0.785"
      upper="0.785"
      effort="0"
      velocity="0" />
  </joint>
  <link
    name="pitch_link_1">
    <inertial>
      <origin
        xyz="-0.0291212003291999 7.90396791684293E-05 -0.244444506995431"
        rpy="0 0 0" />
      <mass
        value="1.42958021062819" />
      <inertia
        ixx="0.00589378373776651"
        ixy="-4.78295159905597E-07"
        ixz="-1.36906399083809E-08"
        iyy="0.00513254533934156"
        iyz="1.37740841479114E-06"
        izz="0.00103475106371056" />
    </inertial>
    <visual>
      <origin
        xyz="0 0 0"
        rpy="0 0 0" />
      <geometry>
        <mesh
          filename="package://robotic_arm/meshes/pitch_link_1.STL" />
      </geometry>
      <material
        name="">
        <color
          rgba="0.752941176470588 0.752941176470588 0.752941176470588 1" />
      </material>
    </visual>
    <collision>
      <origin
        xyz="0 0 0"
        rpy="0 0 0" />
      <geometry>
        <mesh
          filename="package://robotic_arm/meshes/pitch_link_1.STL" />
      </geometry>
    </collision>
  </link>
  <joint
    name="pitch_joint_1"
    type="revolute">
    <origin
      xyz="0 0.09 -0.021"
      rpy="1.5708 1.5708 0" />
    <parent
      link="yaw_link_1" />
    <child
      link="pitch_link_1" />
    <axis
      xyz="-1 0 0" />
    <limit
      lower="-1.395"
      upper="1.395"
      effort="0"
      velocity="0" />
  </joint>
  <link
    name="pitch_link_2">
    <inertial>
      <origin
        xyz="-0.000223730133699525 0.01427592285684 -0.0798055242213448"
        rpy="0 0 0" />
      <mass
        value="0.691986938672532" />
      <inertia
        ixx="0.00278381074345624"
        ixy="-4.80082433953237E-08"
        ixz="3.64795294405893E-07"
        iyy="0.00265055208730543"
        iyz="7.05046016825005E-07"
        izz="0.000293754427083624" />
    </inertial>
    <visual>
      <origin
        xyz="0 0 0"
        rpy="0 0 0" />
      <geometry>
        <mesh
          filename="package://robotic_arm/meshes/pitch_link_2.STL" />
      </geometry>
      <material
        name="">
        <color
          rgba="0.752941176470588 0.752941176470588 0.752941176470588 1" />
      </material>
    </visual>
    <collision>
      <origin
        xyz="0 0 0"
        rpy="0 0 0" />
      <geometry>
        <mesh
          filename="package://robotic_arm/meshes/pitch_link_2.STL" />
      </geometry>
    </collision>
  </link>
  <joint
    name="pitch_joint_2"
    type="revolute">
    <origin
      xyz="-0.0005 0 -0.32"
      rpy="0 0 0" />
    <parent
      link="pitch_link_1" />
    <child
      link="pitch_link_2" />
    <axis
      xyz="-1 0 0" />
    <limit
      lower="-2.355"
      upper="2.355"
      effort="0"
      velocity="0" />
  </joint>
  <link
    name="roll_link_1">
    <inertial>
      <origin
        xyz="2.48215911058001E-06 -0.00701069593560619 -0.0610298343458905"
        rpy="0 0 0" />
      <mass
        value="0.692076783236663" />
      <inertia
        ixx="7.42912905181379E-05"
        ixy="4.47652918481028E-08"
        ixz="3.79162011158385E-08"
        iyy="0.000165935426826622"
        iyz="-5.94928364106857E-09"
        izz="0.000167451112327132" />
    </inertial>
    <visual>
      <origin
        xyz="0 0 0"
        rpy="0 0 0" />
      <geometry>
        <mesh
          filename="package://robotic_arm/meshes/roll_link_1.STL" />
      </geometry>
      <material
        name="">
        <color
          rgba="0.752941176470588 0.752941176470588 0.752941176470588 1" />
      </material>
    </visual>
    <collision>
      <origin
        xyz="0 0 0"
        rpy="0 0 0" />
      <geometry>
        <mesh
          filename="package://robotic_arm/meshes/roll_link_1.STL" />
      </geometry>
    </collision>
  </link>
  <joint
    name="roll_joint_1"
    type="revolute">
    <origin
      xyz="0 6E-05 -0.2609"
      rpy="0 0 -3.1416" />
    <parent
      link="pitch_link_2" />
    <child
      link="roll_link_1" />
    <axis
      xyz="0 0 -1" />
    <limit
      lower="-3.14"
      upper="3.14"
      effort="0"
      velocity="0" />
  </joint>
  <link
    name="pitch_link_3">
    <inertial>
      <origin
        xyz="4.2191721107681E-06 -0.0245906913306897 -0.000251403878043316"
        rpy="0 0 0" />
      <mass
        value="0.0986725042796473" />
      <inertia
        ixx="9.45175928682656E-06"
        ixy="1.03177142691329E-20"
        ixz="-2.27889363152944E-07"
        iyy="2.08585939751818E-05"
        iyz="-9.55383950057282E-09"
        izz="1.58607848374082E-05" />
    </inertial>
    <visual>
      <origin
        xyz="0 0 0"
        rpy="0 0 0" />
      <geometry>
        <mesh
          filename="package://robotic_arm/meshes/pitch_link_3.STL" />
      </geometry>
      <material
        name="">
        <color
          rgba="0.886274509803922 0.843137254901961 0.584313725490196 1" />
      </material>
    </visual>
    <collision>
      <origin
        xyz="0 0 0"
        rpy="0 0 0" />
      <geometry>
        <mesh
          filename="package://robotic_arm/meshes/pitch_link_3.STL" />
      </geometry>
    </collision>
  </link>
  <joint
    name="pitch_joint_3"
    type="revolute">
    <origin
      xyz="0 0.00356 -0.0931"
      rpy="1.5708 0 0.036176" />
    <parent
      link="roll_pitch_1" />
    <child
      link="pitch_link_3" />
    <axis
      xyz="0.99935 0 0.036168" />
    <limit
      lower="-1.57"
      upper="1.57"
      effort="0"
      velocity="0" />
  </joint>
  <link
    name="roll_link_2">
    <inertial>
      <origin
        xyz="-0.000264563470459779 -0.0242983602748746 9.84197916353274E-05"
        rpy="0 0 0" />
      <mass
        value="0.114095126844003" />
      <inertia
        ixx="4.87924079804432E-05"
        ixy="-8.68954123595254E-10"
        ixz="-1.75825443147939E-10"
        iyy="4.70731242813152E-05"
        iyz="-2.40099769075817E-08"
        izz="4.87875561301061E-05" />
    </inertial>
    <visual>
      <origin
        xyz="0 0 0"
        rpy="0 0 0" />
      <geometry>
        <mesh
          filename="package://robotic_arm/meshes/roll_link_2.STL" />
      </geometry>
      <material
        name="">
        <color
          rgba="0.886274509803922 0.843137254901961 0.584313725490196 1" />
      </material>
    </visual>
    <collision>
      <origin
        xyz="0 0 0"
        rpy="0 0 0" />
      <geometry>
        <mesh
          filename="package://robotic_arm/meshes/roll_link_2.STL" />
      </geometry>
    </collision>
  </link>
  <joint
    name="roll_joint_2"
    type="revolute">
    <origin
      xyz="0 -0.03595 7.011E-05"
      rpy="0 -0.036176 0" />
    <parent
      link="pitch_link_3" />
    <child
      link="roll_link_2" />
    <axis
      xyz="0 -1 0" />
    <limit
      lower="-3.14"
      upper="3.14"
      effort="0"
      velocity="0" />
  </joint>
  <link
    name="mine_link">
    <inertial>
      <origin
        xyz="1.90819582357449E-17 0 -6.93889390390723E-18"
        rpy="0 0 0" />
      <mass
        value="7.88533333333335" />
      <inertia
        ixx="0.0516708266666667"
        ixy="4.87043944671223E-18"
        ixz="5.46945794732022E-18"
        iyy="0.0516708266666667"
        iyz="-4.67067391376974E-18"
        izz="0.0516708266666668" />
    </inertial>
    <visual>
      <origin
        xyz="0 0 0"
        rpy="0 0 0" />
      <geometry>
        <mesh
          filename="package://robotic_arm/meshes/mine_link.STL" />
      </geometry>
      <material
        name="">
        <color
          rgba="1 0.964705882352941 0.466666666666667 1" />
      </material>
    </visual>
    <collision>
      <origin
        xyz="0 0 0"
        rpy="0 0 0" />
      <geometry>
        <mesh
          filename="package://robotic_arm/meshes/mine_link.STL" />
      </geometry>
    </collision>
  </link>
  <joint
    name="mine_joint"
    type="fixed">
    <origin
      xyz="-0.00042801 -0.16205 0.0001955"
      rpy="-3.1416 0 0" />
    <parent
      link="roll_link_2" />
    <child
      link="mine_link" />
    <axis
      xyz="0 0 0" />
  </joint>
</robot>