<?xml version="1.0" encoding="utf-8"?>
<!-- This URDF was automatically created by SolidWorks to URDF Exporter! Originally created by Stephen Brawner (brawner@gmail.com) 
     Commit Version: 1.6.0-4-g7f85cfe  Build Version: 1.6.7995.38578
     For more information, please see http://wiki.ros.org/sw_urdf_exporter -->
<robot
  name="robotic_arm">
  <link
    name="base_link">
    <inertial>
      <origin
        xyz="3.545115228575E-18 7.02733317861868E-17 0.005"
        rpy="0 0 0" />
      <mass
        value="0.3" />
      <inertia
        ixx="0.0090025"
        ixy="-4.02961807440446E-20"
        ixz="-1.44560289664731E-22"
        iyy="6.5E-05"
        iyz="5.50919783425842E-19"
        izz="0.0090625" />
    </inertial>
    <visual>
      <origin
        xyz="0 0 0"
        rpy="0 0 0" />
      <geometry>
        <mesh
          filename="package://robotic_arm/meshes/base_link.STL" />
      </geometry>
      <material
        name="">
        <color
          rgba="1 1 1 1" />
      </material>
    </visual>
    <collision>
      <origin
        xyz="0 0 0"
        rpy="0 0 0" />
      <geometry>
        <mesh
          filename="package://robotic_arm/meshes/base_link.STL" />
      </geometry>
    </collision>
  </link>
  <link
    name="second_base_link">
    <inertial>
      <origin
        xyz="-0.044022887337792 -0.0176622667442875 0.0600389088080566"
        rpy="0 0 0" />
      <mass
        value="13.7706626732672" />
      <inertia
        ixx="0.00135146700857453"
        ixy="-2.12203171147033E-08"
        ixz="-1.9401607970181E-06"
        iyy="0.00279077700857323"
        iyz="-3.72530136797397E-08"
        izz="0.0019757045745801" />
    </inertial>
    <visual>
      <origin
        xyz="0 0 0"
        rpy="0 0 0" />
      <geometry>
        <mesh
          filename="package://robotic_arm/meshes/second_base_link.STL" />
      </geometry>
      <material
        name="">
        <color
          rgba="0.752941176470588 0.752941176470588 0.752941176470588 1" />
      </material>
    </visual>
    <collision>
      <origin
        xyz="0 0 0"
        rpy="0 0 0" />
      <geometry>
        <mesh
          filename="package://robotic_arm/meshes/second_base_link.STL" />
      </geometry>
    </collision>
  </link>
  <joint
    name="shift_joint"
    type="prismatic">
    <origin
      xyz="0.025 0 0.0159999999999999"
      rpy="-1.5707963267949 0 -1.5707963267949" />
    <parent
      link="base_link" />
    <child
      link="second_base_link" />
    <axis
      xyz="1 0 0" />
    <limit
      lower="0"
      upper="0"
      effort="0"
      velocity="0" />
  </joint>
  <link
    name="yaw_link_1">
    <inertial>
      <origin
        xyz="4.66964048193019E-07 0.0328590155370009 -0.000362520537038821"
        rpy="0 0 0" />
      <mass
        value="82.2937780685442" />
      <inertia
        ixx="0.0434637013801843"
        ixy="-4.93825912479033E-07"
        ixz="1.77132288546181E-07"
        iyy="0.128350688051016"
        iyz="-8.6307812460472E-08"
        izz="0.0940864524556386" />
    </inertial>
    <visual>
      <origin
        xyz="0 0 0"
        rpy="0 0 0" />
      <geometry>
        <mesh
          filename="package://robotic_arm/meshes/yaw_link_1.STL" />
      </geometry>
      <material
        name="">
        <color
          rgba="0.752941176470588 0.752941176470588 0.752941176470588 1" />
      </material>
    </visual>
    <collision>
      <origin
        xyz="0 0 0"
        rpy="0 0 0" />
      <geometry>
        <mesh
          filename="package://robotic_arm/meshes/yaw_link_1.STL" />
      </geometry>
    </collision>
  </link>
  <joint
    name="yaw_joint_1"
    type="revolute">
    <origin
      xyz="-0.0352368416313989 -0.0370000000000001 0"
      rpy="0 -1.5707963267949 0" />
    <parent
      link="second_base_link" />
    <child
      link="yaw_link_1" />
    <axis
      xyz="0 1 0" />
    <limit
      lower="-0.785"
      upper="0.785"
      effort="0"
      velocity="0" />
  </joint>
  <link
    name="pitch_link_1">
    <inertial>
      <origin
        xyz="6.76805756233342E-05 -0.00204269919053575 0.0795926868026391"
        rpy="0 0 0" />
      <mass
        value="295.934350579955" />
      <inertia
        ixx="0.521077297298085"
        ixy="3.11296490831532E-07"
        ixz="-1.13263447296061E-06"
        iyy="0.288326509824729"
        iyz="-0.00452538527112822"
        izz="0.468276403116782" />
    </inertial>
    <visual>
      <origin
        xyz="0 0 0"
        rpy="0 0 0" />
      <geometry>
        <mesh
          filename="package://robotic_arm/meshes/pitch_link_1.STL" />
      </geometry>
      <material
        name="">
        <color
          rgba="0.752941176470588 0.752941176470588 0.752941176470588 1" />
      </material>
    </visual>
    <collision>
      <origin
        xyz="0 0 0"
        rpy="0 0 0" />
      <geometry>
        <mesh
          filename="package://robotic_arm/meshes/pitch_link_1.STL" />
      </geometry>
    </collision>
  </link>
  <joint
    name="pitch_joint_1"
    type="revolute">
    <origin
      xyz="0 0.0929999999999999 0"
      rpy="3.14159265358979 -1.57079631189374 1.54556245488589" />
    <parent
      link="yaw_link_1" />
    <child
      link="pitch_link_1" />
    <axis
      xyz="1 0 0" />
    <limit
      lower="-1.395"
      upper="1.395"
      effort="0"
      velocity="0" />
  </joint>
  <link
    name="pitch_link_2">
    <inertial>
      <origin
        xyz="-7.86363827882941E-06 -0.0118492706816219 0.0628431163153897"
        rpy="0 0 0" />
      <mass
        value="17.9447761996099" />
      <inertia
        ixx="0.00409983538513512"
        ixy="-2.7842223449585E-08"
        ixz="2.11237619566311E-08"
        iyy="0.00308460062102436"
        iyz="2.03568842417702E-07"
        izz="0.00392292897806876" />
    </inertial>
    <visual>
      <origin
        xyz="0 0 0"
        rpy="0 0 0" />
      <geometry>
        <mesh
          filename="package://robotic_arm/meshes/pitch_link_2.STL" />
      </geometry>
      <material
        name="">
        <color
          rgba="0.752941176470588 0.752941176470588 0.752941176470588 1" />
      </material>
    </visual>
    <collision>
      <origin
        xyz="0 0 0"
        rpy="0 0 0" />
      <geometry>
        <mesh
          filename="package://robotic_arm/meshes/pitch_link_2.STL" />
      </geometry>
    </collision>
  </link>
  <joint
    name="pitch_joint_2"
    type="revolute">
    <origin
      xyz="-0.0005 -0.0070647 0.27991"
      rpy="-1.5456 0 0" />
    <parent
      link="pitch_link_1" />
    <child
      link="pitch_link_2" />
    <axis
      xyz="-1 0 0" />
    <limit
      lower="-2.355"
      upper="2.355"
      effort="0"
      velocity="0" />
  </joint>
  <link
    name="roll_link_1">
    <inertial>
      <origin
        xyz="0.000459875490631929 -0.0438657402293758 3.37810933537762E-05"
        rpy="0 0 0" />
      <mass
        value="76.7289981060703" />
      <inertia
        ixx="0.0312961335815327"
        ixy="-8.61916022090324E-11"
        ixz="4.38036375111009E-06"
        iyy="0.0379769952753597"
        iyz="-2.35626179558082E-05"
        izz="0.0387928626574603" />
    </inertial>
    <visual>
      <origin
        xyz="0 0 0"
        rpy="0 0 0" />
      <geometry>
        <mesh
          filename="package://robotic_arm/meshes/roll_link_1.STL" />
      </geometry>
      <material
        name="">
        <color
          rgba="0.752941176470588 0.752941176470588 0.752941176470588 1" />
      </material>
    </visual>
    <collision>
      <origin
        xyz="0 0 0"
        rpy="0 0 0" />
      <geometry>
        <mesh
          filename="package://robotic_arm/meshes/roll_link_1.STL" />
      </geometry>
    </collision>
  </link>
  <joint
    name="roll_joint_1"
    type="revolute">
    <origin
      xyz="0 -0.28 0"
      rpy="0 0 0" />
    <parent
      link="pitch_link_2" />
    <child
      link="roll_link_1" />
    <axis
      xyz="0 1 0" />
    <limit
      lower="-3.14"
      upper="3.14"
      effort="0"
      velocity="0" />
  </joint>
  <link
    name="pitch_link_3">
    <inertial>
      <origin
        xyz="0.0207723253549985 -0.00639448569451928 -1.79399889483831E-06"
        rpy="0 0 0" />
      <mass
        value="71.4697928533591" />
      <inertia
        ixx="0.0255220344389946"
        ixy="0.000765184353880394"
        ixz="-2.91427652091716E-06"
        iyy="0.0293476093259731"
        iyz="2.46482766481398E-06"
        izz="0.0330881905441518" />
    </inertial>
    <visual>
      <origin
        xyz="0 0 0"
        rpy="0 0 0" />
      <geometry>
        <mesh
          filename="package://robotic_arm/meshes/pitch_link_3.STL" />
      </geometry>
      <material
        name="">
        <color
          rgba="0.929411764705882 0.929411764705882 0.929411764705882 1" />
      </material>
    </visual>
    <collision>
      <origin
        xyz="0 0 0"
        rpy="0 0 0" />
      <geometry>
        <mesh
          filename="package://robotic_arm/meshes/pitch_link_3.STL" />
      </geometry>
    </collision>
  </link>
  <joint
    name="pitch_joint_3"
    type="revolute">
    <origin
      xyz="0.0363 -0.103 0"
      rpy="-3.1366 0 3.1416" />
    <parent
      link="roll_link_1" />
    <child
      link="pitch_link_3" />
    <axis
      xyz="1 0 0" />
    <limit
      lower="-1.57"
      upper="1.57"
      effort="0"
      velocity="0" />
  </joint>
  <link
    name="roll_link_2">
    <inertial>
      <origin
        xyz="3.30422302713407E-08 -0.0242589518113975 5.72308215922301E-08"
        rpy="0 0 0" />
      <mass
        value="41.6646751096041" />
      <inertia
        ixx="0.0324237377311637"
        ixy="-8.8294057338917E-18"
        ixz="2.60208521396521E-18"
        iyy="0.037832723323421"
        iyz="-8.46801529597514E-18"
        izz="0.0324237377311638" />
    </inertial>
    <visual>
      <origin
        xyz="0 0 0"
        rpy="0 0 0" />
      <geometry>
        <mesh
          filename="package://robotic_arm/meshes/roll_link_2.STL" />
      </geometry>
      <material
        name="">
        <color
          rgba="0.647058823529412 0.854901960784314 0.533333333333333 1" />
      </material>
    </visual>
    <collision>
      <origin
        xyz="0 0 0"
        rpy="0 0 0" />
      <geometry>
        <mesh
          filename="package://robotic_arm/meshes/roll_link_2.STL" />
      </geometry>
    </collision>
  </link>
  <joint
    name="roll_joint_2"
    type="revolute">
    <origin
      xyz="0.036315 -0.0345 0.00017249"
      rpy="-3.1304 -1.1081 3.1316" />
    <parent
      link="pitch_link_3" />
    <child
      link="roll_link_2" />
    <axis
      xyz="0 -1 0" />
    <limit
      lower="-3.14"
      upper="3.14"
      effort="0"
      velocity="0" />
  </joint>
</robot>