<?xml version="1.0" encoding="utf-8"?>
<!-- This URDF was automatically created by SolidWorks to URDF Exporter! Originally created by Stephen Brawner (brawner@gmail.com) 
     Commit Version: 1.6.0-4-g7f85cfe  Build Version: 1.6.7995.38578
     For more information, please see http://wiki.ros.org/sw_urdf_exporter -->
<robot
  name="robotic_arm">
  <link
    name="base_link">
    <inertial>
      <origin
        xyz="0.00585101251577283 0.000397441325412592 0.0654322843571715"
        rpy="0 0 0" />
      <mass
        value="54.336001127768" />
      <inertia
        ixx="1.39849259123828"
        ixy="-0.00206378251857883"
        ixz="0.00299896775476267"
        iyy="1.60131759603764"
        iyz="-1.13430515182135E-05"
        izz="2.77208569500992" />
    </inertial>
    <visual>
      <origin
        xyz="0 0 0"
        rpy="0 0 0" />
      <geometry>
        <mesh
          filename="package://robotic_arm/meshes/base_link.STL" />
      </geometry>
      <material
        name="">
        <color
          rgba="1 1 1 1" />
      </material>
    </visual>
    <collision>
      <origin
        xyz="0 0 0"
        rpy="0 0 0" />
      <geometry>
        <mesh
          filename="package://robotic_arm/meshes/base_link.STL" />
      </geometry>
    </collision>
  </link>
  <link
    name="yaw_link_1">
    <inertial>
      <origin
        xyz="0.00870918443354331 -7.1511892201546E-17 0.0852680727788528"
        rpy="0 0 0" />
      <mass
        value="0.801923006913631" />
      <inertia
        ixx="0.0014132967409493"
        ixy="-4.41452899586204E-19"
        ixz="-0.000131007945798482"
        iyy="0.00216705198463788"
        iyz="-5.09151814821158E-19"
        izz="0.00180667712968276" />
    </inertial>
    <visual>
      <origin
        xyz="0 0 0"
        rpy="0 0 0" />
      <geometry>
        <mesh
          filename="package://robotic_arm/meshes/yaw_link_1.STL" />
      </geometry>
      <material
        name="">
        <color
          rgba="1 1 1 1" />
      </material>
    </visual>
    <collision>
      <origin
        xyz="0 0 0"
        rpy="0 0 0" />
      <geometry>
        <mesh
          filename="package://robotic_arm/meshes/yaw_link_1.STL" />
      </geometry>
    </collision>
  </link>
  <joint
    name="yaw_joint_1"
    type="revolute">
    <origin
      xyz="0.14453 0 0.072"
      rpy="0 0 -1.5708" />
    <parent
      link="base_link" />
    <child
      link="yaw_link_1" />
    <axis
      xyz="0 0 -1" />
    <limit
      lower="-0.785"
      upper="0.785"
      effort="0"
      velocity="0" />
  </joint>
  <link
    name="pitch_link_1">
    <inertial>
      <origin
        xyz="0.236024763697292 -4.72640714936388E-17 -0.0130464794165589"
        rpy="0 0 0" />
      <mass
        value="1.1987757736334" />
      <inertia
        ixx="0.00279672770272119"
        ixy="-1.28945118069045E-18"
        ixz="-0.0030246782816463"
        iyy="0.0167854733011717"
        iyz="-6.49065708715282E-19"
        izz="0.0158596408452534" />
    </inertial>
    <visual>
      <origin
        xyz="0 0 0"
        rpy="0 0 0" />
      <geometry>
        <mesh
          filename="package://robotic_arm/meshes/pitch_link_1.STL" />
      </geometry>
      <material
        name="">
        <color
          rgba="0.411764705882353 0.411764705882353 0.411764705882353 1" />
      </material>
    </visual>
    <collision>
      <origin
        xyz="0 0 0"
        rpy="0 0 0" />
      <geometry>
        <mesh
          filename="package://robotic_arm/meshes/pitch_link_1.STL" />
      </geometry>
    </collision>
  </link>
  <joint
    name="pitch_joint_1"
    type="revolute">
    <origin
      xyz="0.03 0 0.094"
      rpy="0 -1.5708 -3.1416" />
    <parent
      link="yaw_link_1" />
    <child
      link="pitch_link_1" />
    <axis
      xyz="0 0 1" />
    <limit
      lower="-0.785"
      upper="0.785"
      effort="0"
      velocity="0" />
  </joint>
  <link
    name="pitch_link_2">
    <inertial>
      <origin
        xyz="0.101220114377187 0.0102969628179878 -0.0385"
        rpy="0 0 0" />
      <mass
        value="1.66680663686079" />
      <inertia
        ixx="0.00210896536001994"
        ixy="0.000608216867399273"
        ixz="-4.66790033546113E-19"
        iyy="0.0165211964220043"
        iyz="-1.78866436742442E-19"
        izz="0.0178099221724609" />
    </inertial>
    <visual>
      <origin
        xyz="0 0 0"
        rpy="0 0 0" />
      <geometry>
        <mesh
          filename="package://robotic_arm/meshes/pitch_link_2.STL" />
      </geometry>
      <material
        name="">
        <color
          rgba="1 1 1 1" />
      </material>
    </visual>
    <collision>
      <origin
        xyz="0 0 0"
        rpy="0 0 0" />
      <geometry>
        <mesh
          filename="package://robotic_arm/meshes/pitch_link_2.STL" />
      </geometry>
    </collision>
  </link>
  <joint
    name="pitch_joint_2"
    type="revolute">
    <origin
      xyz="0.32 0 -0.004"
      rpy="0 0 0" />
    <parent
      link="pitch_link_1" />
    <child
      link="pitch_link_2" />
    <axis
      xyz="0 0 1" />
    <limit
      lower="-2.357"
      upper="2.357"
      effort="0"
      velocity="0" />
  </joint>
  <link
    name="roll_link_1">
    <inertial>
      <origin
        xyz="1.90819582357449E-17 -0.00625495546716607 -0.0506568259577106"
        rpy="0 0 0" />
      <mass
        value="0.299432672842333" />
      <inertia
        ixx="0.000257300376796898"
        ixy="4.16596008172797E-21"
        ixz="4.8242591607809E-20"
        iyy="0.000514551687448403"
        iyz="-7.57771338252382E-06"
        izz="0.000379907267939109" />
    </inertial>
    <visual>
      <origin
        xyz="0 0 0"
        rpy="0 0 0" />
      <geometry>
        <mesh
          filename="package://robotic_arm/meshes/roll_link_1.STL" />
      </geometry>
      <material
        name="">
        <color
          rgba="1 1 1 1" />
      </material>
    </visual>
    <collision>
      <origin
        xyz="0 0 0"
        rpy="0 0 0" />
      <geometry>
        <mesh
          filename="package://robotic_arm/meshes/roll_link_1.STL" />
      </geometry>
    </collision>
  </link>
  <joint
    name="roll_joint_1"
    type="revolute">
    <origin
      xyz="0.354 -0.0015 -0.0385"
      rpy="0 1.5708 0" />
    <parent
      link="pitch_link_2" />
    <child
      link="roll_link_1" />
    <axis
      xyz="0 0 1" />
    <limit
      lower="-3.14"
      upper="3.14"
      effort="0"
      velocity="0" />
  </joint>
  <link
    name="pitch_link_3">
    <inertial>
      <origin
        xyz="1.21430643318376E-17 -1.17093834628434E-17 0.0253814323309287"
        rpy="0 0 0" />
      <mass
        value="0.0292840129670479" />
      <inertia
        ixx="4.81228444047278E-06"
        ixy="-2.10578762748301E-21"
        ixz="-3.85181546862234E-22"
        iyy="1.63695134860614E-05"
        iyz="-2.90702326976073E-22"
        izz="1.54534095466965E-05" />
    </inertial>
    <visual>
      <origin
        xyz="0 0 0"
        rpy="0 0 0" />
      <geometry>
        <mesh
          filename="package://robotic_arm/meshes/pitch_link_3.STL" />
      </geometry>
      <material
        name="">
        <color
          rgba="1 1 1 1" />
      </material>
    </visual>
    <collision>
      <origin
        xyz="0 0 0"
        rpy="0 0 0" />
      <geometry>
        <mesh
          filename="package://robotic_arm/meshes/pitch_link_3.STL" />
      </geometry>
    </collision>
  </link>
  <joint
    name="pitch_joint_3"
    type="revolute">
    <origin
      xyz="0 0 0"
      rpy="0 0 0" />
    <parent
      link="roll_link_1" />
    <child
      link="pitch_link_3" />
    <axis
      xyz="1 0 0" />
    <limit
      lower="-1.57"
      upper="1.57"
      effort="0"
      velocity="0" />
  </joint>
  <link
    name="roll_link_2">
    <inertial>
      <origin
        xyz="2.08166817117217E-17 -5.85469173142172E-17 0.0564499999999999"
        rpy="0 0 0" />
      <mass
        value="0.0375223972563131" />
      <inertia
        ixx="2.89602552323882E-05"
        ixy="2.45639554703747E-21"
        ixz="-5.46003655054376E-21"
        iyy="2.89602552323882E-05"
        iyz="-1.60662139300965E-21"
        izz="3.67015948163313E-05" />
    </inertial>
    <visual>
      <origin
        xyz="0 0 0"
        rpy="0 0 0" />
      <geometry>
        <mesh
          filename="package://robotic_arm/meshes/roll_link_2.STL" />
      </geometry>
      <material
        name="">
        <color
          rgba="1 1 1 1" />
      </material>
    </visual>
    <collision>
      <origin
        xyz="0 0 0"
        rpy="0 0 0" />
      <geometry>
        <mesh
          filename="package://robotic_arm/meshes/roll_link_2.STL" />
      </geometry>
    </collision>
  </link>
  <joint
    name="roll_joint_2"
    type="revolute">
    <origin
      xyz="0 0 0"
      rpy="0 0 0" />
    <parent
      link="pitch_link_3" />
    <child
      link="roll_link_2" />
    <axis
      xyz="0 0 1" />
    <limit
      lower="-3.14"
      upper="3.14"
      effort="0"
      velocity="0" />
  </joint>
  <link
    name="mine_link">
    <inertial>
      <origin
        xyz="-3.29597460435593E-17 -3.90312782094782E-18 0.1"
        rpy="0 0 0" />
      <mass
        value="7.88533333333333" />
      <inertia
        ixx="0.0516708266666666"
        ixy="-4.44692297308508E-18"
        ixz="-2.68401075522813E-18"
        iyy="0.0516708266666666"
        iyz="1.6514788194626E-18"
        izz="0.0516708266666666" />
    </inertial>
    <visual>
      <origin
        xyz="0 0 0"
        rpy="0 0 0" />
      <geometry>
        <mesh
          filename="package://robotic_arm/meshes/mine_link.STL" />
      </geometry>
      <material
        name="">
        <color
          rgba="1 0.964705882352941 0.466666666666667 1" />
      </material>
    </visual>
    <collision>
      <origin
        xyz="0 0 0"
        rpy="0 0 0" />
      <geometry>
        <mesh
          filename="package://robotic_arm/meshes/mine_link.STL" />
      </geometry>
    </collision>
  </link>
  <joint
    name="mine_joint"
    type="fixed">
    <origin
      xyz="0 0 0.08895"
      rpy="0 0 0" />
    <parent
      link="roll_link_2" />
    <child
      link="mine_link" />
    <axis
      xyz="0 0 0" />
  </joint>
</robot>
