<?xml version="1.0" encoding="utf-8"?>
<!-- This URDF was automatically created by SolidWorks to URDF Exporter! Originally created by Stephen Brawner (brawner@gmail.com) 
     Commit Version: 1.6.0-4-g7f85cfe  Build Version: 1.6.7995.38578
     For more information, please see http://wiki.ros.org/sw_urdf_exporter -->
<robot
  name="robotic_arm">
  <link
    name="base_link">
    <inertial>
      <origin
        xyz="-3.68628738645072E-18 -6.91439545231811E-17 0.005"
        rpy="0 0 0" />
      <mass
        value="0.3" />
      <inertia
        ixx="0.0090025"
        ixy="-4.02961807440446E-20"
        ixz="1.44560289664731E-22"
        iyy="6.5E-05"
        iyz="-5.50919783425842E-19"
        izz="0.0090625" />
    </inertial>
    <visual>
      <origin
        xyz="0 0 0"
        rpy="0 0 0" />
      <geometry>
        <mesh
          filename="package://robotic_arm/meshes/base_link.STL" />
      </geometry>
      <material
        name="">
        <color
          rgba="1 1 1 1" />
      </material>
    </visual>
    <collision>
      <origin
        xyz="0 0 0"
        rpy="0 0 0" />
      <geometry>
        <mesh
          filename="package://robotic_arm/meshes/base_link.STL" />
      </geometry>
    </collision>
  </link>
  <link
    name="second_base_link">
    <inertial>
      <origin
        xyz="-0.044022887337792 -0.0176622667442875 0.0600389088080566"
        rpy="0 0 0" />
      <mass
        value="13.7706626732672" />
      <inertia
        ixx="0.00135146700857453"
        ixy="-2.1220317114705E-08"
        ixz="-1.9401607970181E-06"
        iyy="0.00279077700857323"
        iyz="-3.72530136797395E-08"
        izz="0.0019757045745801" />
    </inertial>
    <visual>
      <origin
        xyz="0 0 0"
        rpy="0 0 0" />
      <geometry>
        <mesh
          filename="package://robotic_arm/meshes/second_base_link.STL" />
      </geometry>
      <material
        name="">
        <color
          rgba="0.752941176470588 0.752941176470588 0.752941176470588 1" />
      </material>
    </visual>
    <collision>
      <origin
        xyz="0 0 0"
        rpy="0 0 0" />
      <geometry>
        <mesh
          filename="package://robotic_arm/meshes/second_base_link.STL" />
      </geometry>
    </collision>
  </link>
  <joint
    name="shift_joint"
    type="prismatic">
    <origin
      xyz="-0.025 0 0.016"
      rpy="-1.5708 0 1.5708" />
    <parent
      link="base_link" />
    <child
      link="second_base_link" />
    <axis
      xyz="1 0 0" />
    <limit
      lower="-0.2"
      upper="0.2"
      effort="0"
      velocity="0" />
  </joint>
  <link
    name="yaw_link_1">
    <inertial>
      <origin
        xyz="4.6696404818955E-07 0.0328590155370009 -0.000362520537038807"
        rpy="0 0 0" />
      <mass
        value="82.2937780685442" />
      <inertia
        ixx="0.0434637013801844"
        ixy="-4.93825912479594E-07"
        ixz="1.77132288546177E-07"
        iyy="0.128350688051016"
        iyz="-8.63078124606148E-08"
        izz="0.0940864524556386" />
    </inertial>
    <visual>
      <origin
        xyz="0 0 0"
        rpy="0 0 0" />
      <geometry>
        <mesh
          filename="package://robotic_arm/meshes/yaw_link_1.STL" />
      </geometry>
      <material
        name="">
        <color
          rgba="0.752941176470588 0.752941176470588 0.752941176470588 1" />
      </material>
    </visual>
    <collision>
      <origin
        xyz="0 0 0"
        rpy="0 0 0" />
      <geometry>
        <mesh
          filename="package://robotic_arm/meshes/yaw_link_1.STL" />
      </geometry>
    </collision>
  </link>
  <joint
    name="yaw_joint_1"
    type="revolute">
    <origin
      xyz="-0.035237 -0.037 0"
      rpy="0 -1.5708 -3.1416" />
    <parent
      link="second_base_link" />
    <child
      link="yaw_link_1" />
    <axis
      xyz="0 1 0" />
    <limit
      lower="-0.785"
      upper="0.785"
      effort="0"
      velocity="0" />
  </joint>
  <link
    name="pitch_link_1">
    <inertial>
      <origin
        xyz="6.76805756233204E-05 -0.00204269919053574 0.0795926868026391"
        rpy="0 0 0" />
      <mass
        value="295.934350579955" />
      <inertia
        ixx="0.521077297298085"
        ixy="3.11296490831532E-07"
        ixz="-1.13263447296068E-06"
        iyy="0.288326509824729"
        iyz="-0.00452538527112823"
        izz="0.468276403116782" />
    </inertial>
    <visual>
      <origin
        xyz="0 0 0"
        rpy="0 0 0" />
      <geometry>
        <mesh
          filename="package://robotic_arm/meshes/pitch_link_1.STL" />
      </geometry>
      <material
        name="">
        <color
          rgba="0.752941176470588 0.752941176470588 0.752941176470588 1" />
      </material>
    </visual>
    <collision>
      <origin
        xyz="0 0 0"
        rpy="0 0 0" />
      <geometry>
        <mesh
          filename="package://robotic_arm/meshes/pitch_link_1.STL" />
      </geometry>
    </collision>
  </link>
  <joint
    name="pitch_joint_1"
    type="revolute">
    <origin
      xyz="0 0.093 0"
      rpy="3.1416 -1.5708 1.5456" />
    <parent
      link="yaw_link_1" />
    <child
      link="pitch_link_1" />
    <axis
      xyz="1 0 0" />
    <limit
      lower="-1.395"
      upper="1.395"
      effort="0"
      velocity="0" />
  </joint>
  <link
    name="pitch_link_2">
    <inertial>
      <origin
        xyz="-7.86363827882941E-06 -0.0118492706816219 0.0628431163153897"
        rpy="0 0 0" />
      <mass
        value="17.9447761996099" />
      <inertia
        ixx="0.00409983538513512"
        ixy="-2.78422234495853E-08"
        ixz="2.11237619566301E-08"
        iyy="0.00308460062102436"
        iyz="2.03568842417699E-07"
        izz="0.00392292897806876" />
    </inertial>
    <visual>
      <origin
        xyz="0 0 0"
        rpy="0 0 0" />
      <geometry>
        <mesh
          filename="package://robotic_arm/meshes/pitch_link_2.STL" />
      </geometry>
      <material
        name="">
        <color
          rgba="0.752941176470588 0.752941176470588 0.752941176470588 1" />
      </material>
    </visual>
    <collision>
      <origin
        xyz="0 0 0"
        rpy="0 0 0" />
      <geometry>
        <mesh
          filename="package://robotic_arm/meshes/pitch_link_2.STL" />
      </geometry>
    </collision>
  </link>
  <joint
    name="pitch_joint_2"
    type="revolute">
    <origin
      xyz="-0.0005 -0.0070647 0.27991"
      rpy="-1.5456 0 0" />
    <parent
      link="pitch_link_1" />
    <child
      link="pitch_link_2" />
    <axis
      xyz="-1 0 0" />
    <limit
      lower="-2.355"
      upper="2.355"
      effort="0"
      velocity="0" />
  </joint>
  <link
    name="roll_link_1">
    <inertial>
      <origin
        xyz="0.000459875490631909 -0.0438657402293754 3.37810933538248E-05"
        rpy="0 0 0" />
      <mass
        value="76.7289981060704" />
      <inertia
        ixx="0.0312961335815327"
        ixy="-8.61916025443439E-11"
        ixz="4.38036375110989E-06"
        iyy="0.0379769952753597"
        iyz="-2.35626179558078E-05"
        izz="0.0387928626574603" />
    </inertial>
    <visual>
      <origin
        xyz="0 0 0"
        rpy="0 0 0" />
      <geometry>
        <mesh
          filename="package://robotic_arm/meshes/roll_link_1.STL" />
      </geometry>
      <material
        name="">
        <color
          rgba="0.752941176470588 0.752941176470588 0.752941176470588 1" />
      </material>
    </visual>
    <collision>
      <origin
        xyz="0 0 0"
        rpy="0 0 0" />
      <geometry>
        <mesh
          filename="package://robotic_arm/meshes/roll_link_1.STL" />
      </geometry>
    </collision>
  </link>
  <joint
    name="roll_joint_1"
    type="revolute">
    <origin
      xyz="0 -0.28 0"
      rpy="0 0 0" />
    <parent
      link="pitch_link_2" />
    <child
      link="roll_link_1" />
    <axis
      xyz="0 1 0" />
    <limit
      lower="-3.14"
      upper="3.14"
      effort="0"
      velocity="0" />
  </joint>
  <link
    name="pitch_link_3">
    <inertial>
      <origin
        xyz="0.0207723253549985 -0.0063944856945195 -1.79399889484524E-06"
        rpy="0 0 0" />
      <mass
        value="71.4697928533591" />
      <inertia
        ixx="0.0255220344389946"
        ixy="0.000765184353880393"
        ixz="-2.914276520917E-06"
        iyy="0.0293476093259731"
        iyz="2.46482766481145E-06"
        izz="0.0330881905441518" />
    </inertial>
    <visual>
      <origin
        xyz="0 0 0"
        rpy="0 0 0" />
      <geometry>
        <mesh
          filename="package://robotic_arm/meshes/pitch_link_3.STL" />
      </geometry>
      <material
        name="">
        <color
          rgba="0.929411764705882 0.929411764705882 0.929411764705882 1" />
      </material>
    </visual>
    <collision>
      <origin
        xyz="0 0 0"
        rpy="0 0 0" />
      <geometry>
        <mesh
          filename="package://robotic_arm/meshes/pitch_link_3.STL" />
      </geometry>
    </collision>
  </link>
  <joint
    name="pitch_joint_3"
    type="revolute">
    <origin
      xyz="0.0363 -0.103 0"
      rpy="-3.1366 0 3.1416" />
    <parent
      link="roll_link_1" />
    <child
      link="pitch_link_3" />
    <axis
      xyz="1 0 0" />
    <limit
      lower="-1.57"
      upper="1.57"
      effort="0"
      velocity="0" />
  </joint>
  <link
    name="roll_link_2">
    <inertial>
      <origin
        xyz="3.30422302782796E-08 -0.0242589518113975 5.7230821599169E-08"
        rpy="0 0 0" />
      <mass
        value="41.6646751096041" />
      <inertia
        ixx="0.0324237377311637"
        ixy="-8.82828137240354E-18"
        ixz="-3.46944695195361E-18"
        iyy="0.037832723323421"
        iyz="-8.46926854587924E-18"
        izz="0.0324237377311638" />
    </inertial>
    <visual>
      <origin
        xyz="0 0 0"
        rpy="0 0 0" />
      <geometry>
        <mesh
          filename="package://robotic_arm/meshes/roll_link_2.STL" />
      </geometry>
      <material
        name="">
        <color
          rgba="0.647058823529412 0.854901960784314 0.533333333333333 1" />
      </material>
    </visual>
    <collision>
      <origin
        xyz="0 0 0"
        rpy="0 0 0" />
      <geometry>
        <mesh
          filename="package://robotic_arm/meshes/roll_link_2.STL" />
      </geometry>
    </collision>
  </link>
  <joint
    name="roll_joint_2"
    type="revolute">
    <origin
      xyz="0.036315 -0.0345 0.00017249"
      rpy="-3.1304 -1.1081 3.1316" />
    <parent
      link="pitch_link_3" />
    <child
      link="roll_link_2" />
    <axis
      xyz="0 1 0" />
    <limit
      lower="-3.14"
      upper="3.14"
      effort="0"
      velocity="0" />
  </joint>
</robot>
