<?xml version="1.0" encoding="utf-8"?>
<!-- This URDF was automatically created by SolidWorks to URDF Exporter! Originally created by Stephen Brawner (brawner@gmail.com) 
     Commit Version: 1.6.0-4-g7f85cfe  Build Version: 1.6.7995.38578
     For more information, please see http://wiki.ros.org/sw_urdf_exporter -->
<robot
  name="robotic_arm">
  <link
    name="base_link">
    <inertial>
      <origin
        xyz="-0.0601350609443195 -0.000191052613252042 0.0177756973078393"
        rpy="0 0 0" />
      <mass
        value="13.7282221837119" />
      <inertia
        ixx="0.00160094630388113"
        ixy="-2.13664839114172E-06"
        ixz="3.06716674469022E-08"
        iyy="0.00129812149683772"
        iyz="-1.73790534019768E-08"
        izz="0.00236445813683244" />
    </inertial>
    <visual>
      <origin
        xyz="0 0 0"
        rpy="0 0 0" />
      <geometry>
        <mesh
          filename="package://robotic_arm/meshes/base_link.STL" />
      </geometry>
      <material
        name="">
        <color
          rgba="0.752941176470588 0.752941176470588 0.752941176470588 1" />
      </material>
    </visual>
    <collision>
      <origin
        xyz="0 0 0"
        rpy="0 0 0" />
      <geometry>
        <mesh
          filename="package://robotic_arm/meshes/base_link.STL" />
      </geometry>
    </collision>
  </link>
  <link
    name="yaw_link_1">
    <inertial>
      <origin
        xyz="-0.000214391912453599 -4.36929204152337E-07 0.0672722688022909"
        rpy="0 0 0" />
      <mass
        value="87.9507153037812" />
      <inertia
        ixx="0.110169435761554"
        ixy="1.77132287604711E-07"
        ixz="8.630781242809E-08"
        iyy="0.0496641707722624"
        iyz="4.93825912234643E-07"
        izz="0.144817070181327" />
    </inertial>
    <visual>
      <origin
        xyz="0 0 0"
        rpy="0 0 0" />
      <geometry>
        <mesh
          filename="package://robotic_arm/meshes/yaw_link_1.STL" />
      </geometry>
      <material
        name="">
        <color
          rgba="0.752941176470588 0.752941176470588 0.752941176470588 1" />
      </material>
    </visual>
    <collision>
      <origin
        xyz="0 0 0"
        rpy="0 0 0" />
      <geometry>
        <mesh
          filename="package://robotic_arm/meshes/yaw_link_1.STL" />
      </geometry>
    </collision>
  </link>
  <joint
    name="yaw_joint_1"
    type="revolute">
    <origin
      xyz="0 0 0"
      rpy="0 0 -1.5708" />
    <parent
      link="base_link" />
    <child
      link="yaw_link_1" />
    <axis
      xyz="0 0 1" />
    <limit
      lower="-0.785"
      upper="0.785"
      effort="0"
      velocity="0" />
  </joint>
  <link
    name="pitch_link_1">
    <inertial>
      <origin
        xyz="-5.30568850129644E-05 -1.58593785088234E-07 0.0788494629218575"
        rpy="0 0 0" />
      <mass
        value="295.252993054117" />
      <inertia
        ixx="0.521180522124424"
        ixy="2.82705654585392E-07"
        ixz="-1.14822632909463E-06"
        iyy="0.288403748026872"
        iyz="-1.02460679622686E-07"
        izz="0.468708525928736" />
    </inertial>
    <visual>
      <origin
        xyz="0 0 0"
        rpy="0 0 0" />
      <geometry>
        <mesh
          filename="package://robotic_arm/meshes/pitch_link_1.STL" />
      </geometry>
      <material
        name="">
        <color
          rgba="0.752941176470588 0.752941176470588 0.752941176470588 1" />
      </material>
    </visual>
    <collision>
      <origin
        xyz="0 0 0"
        rpy="0 0 0" />
      <geometry>
        <mesh
          filename="package://robotic_arm/meshes/pitch_link_1.STL" />
      </geometry>
    </collision>
  </link>
  <joint
    name="pitch_joint_1"
    type="revolute">
    <origin
      xyz="0.0005 0 0.13"
      rpy="0 0 3.1416" />
    <parent
      link="yaw_link_1" />
    <child
      link="pitch_link_1" />
    <axis
      xyz="-1 0 0" />
    <limit
      lower="-1.395"
      upper="1.395"
      effort="0"
      velocity="0" />
  </joint>
  <link
    name="pitch_link_2">
    <inertial>
      <origin
        xyz="-0.0332172455500475 -0.0121738253162383 -0.0559446784766097"
        rpy="0 0 0" />
      <mass
        value="70.0598135901435" />
      <inertia
        ixx="0.0358100430639193"
        ixy="0.000469262738612684"
        ixz="-0.000483637222088824"
        iyy="0.0318685423412057"
        iyz="-0.00784936002835097"
        izz="0.037833112085771" />
    </inertial>
    <visual>
      <origin
        xyz="0 0 0"
        rpy="0 0 0" />
      <geometry>
        <mesh
          filename="package://robotic_arm/meshes/pitch_link_2.STL" />
      </geometry>
      <material
        name="">
        <color
          rgba="0.752941176470588 0.752941176470588 0.752941176470588 1" />
      </material>
    </visual>
    <collision>
      <origin
        xyz="0 0 0"
        rpy="0 0 0" />
      <geometry>
        <mesh
          filename="package://robotic_arm/meshes/pitch_link_2.STL" />
      </geometry>
    </collision>
  </link>
  <joint
    name="pitch_joint_2"
    type="revolute">
    <origin
      xyz="0.033 0 0.32"
      rpy="1.5708 0 0" />
    <parent
      link="pitch_link_1" />
    <child
      link="pitch_link_2" />
    <axis
      xyz="-1 0 0" />
    <limit
      lower="-2.355"
      upper="2.355"
      effort="0"
      velocity="0" />
  </joint>
  <link
    name="roll_link_1">
    <inertial>
      <origin
        xyz="4.81311141333277E-10 0.0418971290137079 -4.28326164009331E-05"
        rpy="0 0 0" />
      <mass
        value="60.5862745242004" />
      <inertia
        ixx="0.030100826858208"
        ixy="1.55312776093209E-10"
        ixz="-4.52676084768941E-06"
        iyy="0.0372366386625333"
        iyz="-2.35626254164356E-05"
        izz="0.038081604796367" />
    </inertial>
    <visual>
      <origin
        xyz="0 0 0"
        rpy="0 0 0" />
      <geometry>
        <mesh
          filename="package://robotic_arm/meshes/roll_link_1.STL" />
      </geometry>
      <material
        name="">
        <color
          rgba="0.752941176470588 0.752941176470588 0.752941176470588 1" />
      </material>
    </visual>
    <collision>
      <origin
        xyz="0 0 0"
        rpy="0 0 0" />
      <geometry>
        <mesh
          filename="package://robotic_arm/meshes/roll_link_1.STL" />
      </geometry>
    </collision>
  </link>
  <joint
    name="roll_joint_1"
    type="revolute">
    <origin
      xyz="-0.0335 0.24 0"
      rpy="0 0 0" />
    <parent
      link="pitch_link_2" />
    <child
      link="roll_link_1" />
    <axis
      xyz="0 -1 0" />
    <limit
      lower="-3.14"
      upper="3.14"
      effort="0"
      velocity="0" />
  </joint>
  <link
    name="pitch_link_3">
    <inertial>
      <origin
        xyz="0.0225812277098407 -0.00513195408393052 -3.55924035213367E-05"
        rpy="0 0 0" />
      <mass
        value="67.7985905410719" />
      <inertia
        ixx="0.0251588389841772"
        ixy="0.000765189360393249"
        ixz="9.1146810216248E-07"
        iyy="0.0286336852586303"
        iyz="-1.62364968472307E-05"
        izz="0.0327249262358526" />
    </inertial>
    <visual>
      <origin
        xyz="0 0 0"
        rpy="0 0 0" />
      <geometry>
        <mesh
          filename="package://robotic_arm/meshes/pitch_link_3.STL" />
      </geometry>
      <material
        name="">
        <color
          rgba="0.929411764705882 0.929411764705882 0.929411764705882 1" />
      </material>
    </visual>
    <collision>
      <origin
        xyz="0 0 0"
        rpy="0 0 0" />
      <geometry>
        <mesh
          filename="package://robotic_arm/meshes/pitch_link_3.STL" />
      </geometry>
    </collision>
  </link>
  <joint
    name="pitch_joint_3"
    type="revolute">
    <origin
      xyz="0.038981 0.103 0"
      rpy="0 0 -3.1416" />
    <parent
      link="roll_link_1" />
    <child
      link="pitch_link_3" />
    <axis
      xyz="1 0 0" />
    <limit
      lower="-1.57"
      upper="1.57"
      effort="0"
      velocity="0" />
  </joint>
  <link
    name="roll_link_2">
    <inertial>
      <origin
        xyz="0.0146329227098057 -2.38524477946811E-18 3.86863859237568E-15"
        rpy="0 0 0" />
      <mass
        value="47.4654306133547" />
      <inertia
        ixx="0.0703917654370654"
        ixy="-1.11497792116065E-17"
        ixz="-3.18756489065158E-18"
        iyy="0.0448196258448108"
        iyz="9.9924353690621E-19"
        izz="0.0448196258448108" />
    </inertial>
    <visual>
      <origin
        xyz="0 0 0"
        rpy="0 0 0" />
      <geometry>
        <mesh
          filename="package://robotic_arm/meshes/roll_link_2.STL" />
      </geometry>
      <material
        name="">
        <color
          rgba="0.698039215686274 0.698039215686274 0.698039215686274 1" />
      </material>
    </visual>
    <collision>
      <origin
        xyz="0 0 0"
        rpy="0 0 0" />
      <geometry>
        <mesh
          filename="package://robotic_arm/meshes/roll_link_2.STL" />
      </geometry>
    </collision>
  </link>
  <joint
    name="roll_joint_2"
    type="revolute">
    <origin
      xyz="0.038966 -0.039002 0"
      rpy="-3.1416 0 -1.5708" />
    <parent
      link="pitch_link_3" />
    <child
      link="roll_link_2" />
    <axis
      xyz="1 0 0" />
    <limit
      lower="-3.14"
      upper="3.14"
      effort="0"
      velocity="0" />
  </joint>
</robot>
